Workbook
Name densidad: DATINF!$C$1:$C$20

Sheet DATINF
A1: Fecha entrada (ensayo)
A2: Fecha informe (firma)
A3: Tipo | C3: 2 | D3: 1 | E3: 3
A4: Obra
A5: Ref Obra
A6: mmuestra
A7: Orden trabajo | D7: =SUBSTITUTE(C7,"/","_")
A8: Localización
A9: Destinatario1
A11: Destinatario2
A13: Destinatario3
A15: Destinatario4
A17: Destinatario5
A19: Nº de lote
A20: Número primer ensayo
A21: Número de ensayos
A22: Observaciones
A24: Nº ensayo | C24: LABORATORIO | E24: OBRA | K24: VALORACIÓN
C25: D máx. g/cm3 | D25: H ópt. % | E25: D "in situ" g/cm3 | F25: H "in situ" % | G25: % Compac-tación | I25: Media? | K25: =CONCATENATE("Especificaciones >= ",K57,"% ",F57) -> Especificaciones >= 100% PM
A26: =IF(C20="","",C20) | G26: =IF(A26="","",E26/C26*100) | H26: =IF(A26="","",E26/C26*100) | I26: 1 | L26: =$G$42 -> #DIV/0! | M26: =IF(I26=1,IF(A26="",#N/A,E26/C26*100),#N/A) -> #N/A | N26: =IF(I26=0,"",G26) | O26: =$G$42 -> #DIV/0! | P26: =$K$57 -> 100 | Q26: =P26-0.05 -> 99.95 | S26: =P26*0.01 -> 1
A27: =IF(ISERROR(IF(A26+1<=$A$26+$C$21-1,A26+1,#N/A)),"",IF(A26+1<=$A$26+$C$21-1,A26+1,#N/A)) | C27: =IF(A27="",#N/A,IF(C26="",#N/A,C26)) -> #N/A | D27: =IF(A27="",#N/A,IF(D26="",#N/A,D26)) -> #N/A | G27: =IF(A27="","",E27/C27*100) | H27: =IF(A27="","",E27/C27*100) | I27: 1 | L27: =$G$42 -> #DIV/0! | M27: =IF(I27=1,IF(A27="",#N/A,E27/C27*100),#N/A) -> #N/A | N27: =IF(I27=0,"",G27) | O27: =$G$42 -> #DIV/0! | P27: =$K$57 -> 100 | Q27: =P27-0.05 -> 99.95
A28: =IF(ISERROR(IF(A27+1<=$A$26+$C$21-1,A27+1,#N/A)),"",IF(A27+1<=$A$26+$C$21-1,A27+1,#N/A)) | C28: =IF(A28="",#N/A,IF(C27="",#N/A,C27)) -> #N/A | D28: =IF(A28="",#N/A,IF(D27="",#N/A,D27)) -> #N/A | G28: =IF(A28="","",E28/C28*100) | H28: =IF(A28="","",E28/C28*100) | I28: 1 | L28: =$G$42 -> #DIV/0! | M28: =IF(I28=1,IF(A28="",#N/A,E28/C28*100),#N/A) -> #N/A | N28: =IF(I28=0,"",G28) | O28: =$G$42 -> #DIV/0! | P28: =$K$57 -> 100 | Q28: =P28-0.05 -> 99.95
A29: =IF(ISERROR(IF(A28+1<=$A$26+$C$21-1,A28+1,#N/A)),"",IF(A28+1<=$A$26+$C$21-1,A28+1,#N/A)) | C29: =IF(A29="",#N/A,IF(C28="",#N/A,C28)) -> #N/A | D29: =IF(A29="",#N/A,IF(D28="",#N/A,D28)) -> #N/A | G29: =IF(A29="","",E29/C29*100) | H29: =IF(A29="","",E29/C29*100) | I29: 1 | L29: =$G$42 -> #DIV/0! | M29: =IF(I29=1,IF(A29="",#N/A,E29/C29*100),#N/A) -> #N/A | N29: =IF(I29=0,"",G29) | O29: =$G$42 -> #DIV/0! | P29: =$K$57 -> 100 | Q29: =P29-0.05 -> 99.95
A30: =IF(ISERROR(IF(A29+1<=$A$26+$C$21-1,A29+1,#N/A)),"",IF(A29+1<=$A$26+$C$21-1,A29+1,#N/A)) | C30: =IF(A30="",#N/A,IF(C29="",#N/A,C29)) -> #N/A | D30: =IF(A30="",#N/A,IF(D29="",#N/A,D29)) -> #N/A | G30: =IF(A30="","",E30/C30*100) | H30: =IF(A30="","",E30/C30*100) | I30: 1 | L30: =$G$42 -> #DIV/0! | M30: =IF(I30=1,IF(A30="",#N/A,E30/C30*100),#N/A) -> #N/A | N30: =IF(I30=0,"",G30) | O30: =$G$42 -> #DIV/0! | P30: =$K$57 -> 100 | Q30: =P30-0.05 -> 99.95
A31: =IF(ISERROR(IF(A30+1<=$A$26+$C$21-1,A30+1,#N/A)),"",IF(A30+1<=$A$26+$C$21-1,A30+1,#N/A)) | C31: =IF(A31="",#N/A,IF(C30="",#N/A,C30)) -> #N/A | D31: =IF(A31="",#N/A,IF(D30="",#N/A,D30)) -> #N/A | G31: =IF(A31="","",E31/C31*100) | H31: =IF(A31="","",E31/C31*100) | I31: 1 | L31: =$G$42 -> #DIV/0! | M31: =IF(I31=1,IF(A31="",#N/A,E31/C31*100),#N/A) -> #N/A | N31: =IF(I31=0,"",G31) | O31: =$G$42 -> #DIV/0! | P31: =$K$57 -> 100 | Q31: =P31-0.05 -> 99.95
A32: =IF(ISERROR(IF(A31+1<=$A$26+$C$21-1,A31+1,#N/A)),"",IF(A31+1<=$A$26+$C$21-1,A31+1,#N/A)) | C32: =IF(A32="",#N/A,IF(C31="",#N/A,C31)) -> #N/A | D32: =IF(A32="",#N/A,IF(D31="",#N/A,D31)) -> #N/A | G32: =IF(A32="","",E32/C32*100) | H32: =IF(A32="","",E32/C32*100) | I32: 1 | L32: =$G$42 -> #DIV/0! | M32: =IF(I32=1,IF(A32="",#N/A,E32/C32*100),#N/A) -> #N/A | N32: =IF(I32=0,"",G32) | O32: =$G$42 -> #DIV/0! | P32: =$K$57 -> 100 | Q32: =P32-0.05 -> 99.95
A33: =IF(ISERROR(IF(A32+1<=$A$26+$C$21-1,A32+1,#N/A)),"",IF(A32+1<=$A$26+$C$21-1,A32+1,#N/A)) | C33: =IF(A33="",#N/A,IF(C32="",#N/A,C32)) -> #N/A | D33: =IF(A33="",#N/A,IF(D32="",#N/A,D32)) -> #N/A | G33: =IF(A33="","",E33/C33*100) | H33: =IF(A33="","",E33/C33*100) | I33: 1 | L33: =$G$42 -> #DIV/0! | M33: =IF(I33=1,IF(A33="",#N/A,E33/C33*100),#N/A) -> #N/A | N33: =IF(I33=0,"",G33) | O33: =$G$42 -> #DIV/0! | P33: =$K$57 -> 100 | Q33: =P33-0.05 -> 99.95
A34: =IF(ISERROR(IF(A33+1<=$A$26+$C$21-1,A33+1,#N/A)),"",IF(A33+1<=$A$26+$C$21-1,A33+1,#N/A)) | C34: =IF(A34="",#N/A,IF(C33="",#N/A,C33)) -> #N/A | D34: =IF(A34="",#N/A,IF(D33="",#N/A,D33)) -> #N/A | G34: =IF(A34="","",E34/C34*100) | H34: =IF(A34="","",E34/C34*100) | I34: 1 | L34: =$G$42 -> #DIV/0! | M34: =IF(I34=1,IF(A34="",#N/A,E34/C34*100),#N/A) -> #N/A | N34: =IF(I34=0,"",G34) | O34: =$G$42 -> #DIV/0! | P34: =$K$57 -> 100 | Q34: =P34-0.05 -> 99.95
A35: =IF(ISERROR(IF(A34+1<=$A$26+$C$21-1,A34+1,#N/A)),"",IF(A34+1<=$A$26+$C$21-1,A34+1,#N/A)) | C35: =IF(A35="",#N/A,IF(C34="",#N/A,C34)) -> #N/A | D35: =IF(A35="",#N/A,IF(D34="",#N/A,D34)) -> #N/A | G35: =IF(A35="","",E35/C35*100) | H35: =IF(A35="","",E35/C35*100) | I35: 1 | L35: =$G$42 -> #DIV/0! | M35: =IF(I35=1,IF(A35="",#N/A,E35/C35*100),#N/A) -> #N/A | N35: =IF(I35=0,"",G35) | O35: =$G$42 -> #DIV/0! | P35: =$K$57 -> 100 | Q35: =P35-0.05 -> 99.95
A36: =IF(ISERROR(IF(A35+1<=$A$26+$C$21-1,A35+1,#N/A)),"",IF(A35+1<=$A$26+$C$21-1,A35+1,#N/A)) | C36: =IF(A36="",#N/A,IF(C35="",#N/A,C35)) -> #N/A | D36: =IF(A36="",#N/A,IF(D35="",#N/A,D35)) -> #N/A | G36: =IF(A36="","",E36/C36*100) | H36: =IF(A36="","",E36/C36*100) | I36: 1 | L36: =$G$42 -> #DIV/0! | M36: =IF(I36=1,IF(A36="",#N/A,E36/C36*100),#N/A) -> #N/A | N36: =IF(I36=0,"",G36) | O36: =$G$42 -> #DIV/0! | P36: =$K$57 -> 100 | Q36: =P36-0.05 -> 99.95
A37: =IF(ISERROR(IF(A36+1<=$A$26+$C$21-1,A36+1,#N/A)),"",IF(A36+1<=$A$26+$C$21-1,A36+1,#N/A)) | C37: =IF(A37="",#N/A,IF(C36="",#N/A,C36)) -> #N/A | D37: =IF(A37="",#N/A,IF(D36="",#N/A,D36)) -> #N/A | G37: =IF(A37="","",E37/C37*100) | H37: =IF(A37="","",E37/C37*100) | I37: 1 | L37: =$G$42 -> #DIV/0! | M37: =IF(I37=1,IF(A37="",#N/A,E37/C37*100),#N/A) -> #N/A | N37: =IF(I37=0,"",G37) | O37: =$G$42 -> #DIV/0! | P37: =$K$57 -> 100 | Q37: =P37-0.05 -> 99.95
A38: =IF(ISERROR(IF(A37+1<=$A$26+$C$21-1,A37+1,#N/A)),"",IF(A37+1<=$A$26+$C$21-1,A37+1,#N/A)) | C38: =IF(A38="",#N/A,IF(C37="",#N/A,C37)) -> #N/A | D38: =IF(A38="",#N/A,IF(D37="",#N/A,D37)) -> #N/A | G38: =IF(A38="","",E38/C38*100) | H38: =IF(A38="","",E38/C38*100) | I38: 1 | L38: =$G$42 -> #DIV/0! | M38: =IF(I38=1,IF(A38="",#N/A,E38/C38*100),#N/A) -> #N/A | N38: =IF(I38=0,"",G38) | O38: =$G$42 -> #DIV/0! | P38: =$K$57 -> 100 | Q38: =P38-0.05 -> 99.95
A39: =IF(ISERROR(IF(A38+1<=$A$26+$C$21-1,A38+1,#N/A)),"",IF(A38+1<=$A$26+$C$21-1,A38+1,#N/A)) | C39: =IF(A39="",#N/A,IF(C38="",#N/A,C38)) -> #N/A | D39: =IF(A39="",#N/A,IF(D38="",#N/A,D38)) -> #N/A | G39: =IF(A39="","",E39/C39*100) | H39: =IF(A39="","",E39/C39*100) | I39: 1 | K39: =IF(E39="","",F39/G39*100) | L39: =$G$42 -> #DIV/0! | M39: =IF(I39=1,IF(A39="",#N/A,E39/C39*100),#N/A) -> #N/A | N39: =IF(I39=0,"",G39) | O39: =$G$42 -> #DIV/0! | P39: =$K$57 -> 100 | Q39: =P39-0.05 -> 99.95
A40: =IF(ISERROR(IF(A39+1<=$A$26+$C$21-1,A39+1,#N/A)),"",IF(A39+1<=$A$26+$C$21-1,A39+1,#N/A)) | C40: =IF(A40="",#N/A,IF(C39="",#N/A,C39)) -> #N/A | D40: =IF(A40="",#N/A,IF(D39="",#N/A,D39)) -> #N/A | G40: =IF(A40="","",E40/C40*100) | H40: =IF(A40="","",E40/C40*100) | I40: 1 | L40: =$G$42 -> #DIV/0! | M40: =IF(I40=1,IF(A40="",#N/A,E40/C40*100),#N/A) -> #N/A | N40: =IF(I40=0,"",G40) | O40: =$G$42 -> #DIV/0! | P40: =$K$57 -> 100 | Q40: =P40-0.05 -> 99.95
A41: =IF(ISERROR(IF(A40+1<=$A$26+$C$21-1,A40+1,#N/A)),"",IF(A40+1<=$A$26+$C$21-1,A40+1,#N/A)) | C41: =IF(A41="",#N/A,IF(C40="",#N/A,C40)) -> #N/A | D41: =IF(A41="",#N/A,IF(D40="",#N/A,D40)) -> #N/A | G41: =IF(A41="","",E41/C41*100) | H41: =IF(A41="","",E41/C41*100) | I41: 1 | L41: =$G$42 -> #DIV/0! | M41: =IF(I41=1,IF(A41="",#N/A,E41/C41*100),#N/A) -> #N/A | N41: =IF(I41=0,"",G41) | O41: =$G$42 -> #DIV/0! | P41: =$K$57 -> 100 | Q41: =P41-0.05 -> 99.95
A42: MEDIA LOTE | E42: =AVERAGE(E26:E41) -> #DIV/0! | F42: =AVERAGE(F26:F41) -> #DIV/0! | G42: =AVERAGE(N26:N41) -> #DIV/0! | K42: =IF(AVERAGE(G26:G41)>G57,"CUMPLE","NO CUMPLE") -> #DIV/0!
A43: COEFICIENTE DE VARIACIÓN, V% | E43: =100*STDEV(E26:E41)/E42 -> #DIV/0! | F43: =100*STDEV(F26:F41)/F42 -> #DIV/0! | G43: =100*STDEV(N26:N41)/G42 -> #DIV/0!
A47: Escala eje valores Y
A48: Mínimo | B48: 88
A49: Máximo | B49: 105
...

Sheet INF
A2: INFORME DE ENSAYO DE DENSIDAD Y HUMEDAD "IN SITU" (por isótopos radiactivos ASTM D-6938)
A4: =CONCATENATE("Obra: ",DATINF!C4) -> Obra:
A5: =CONCATENATE("Ref. Obra: ",DATINF!C5) -> Ref. Obra: | C5: =CONCATENATE("Orden de trabajo: ",DATINF!C7) -> Orden de trabajo: | G5: =CONCATENATE("Capa: ",VLOOKUP(DATINF!C3,DATINF!A57:B65,2)) -> Capa: Coronación
A6: =CONCATENATE("Localización: ",DATINF!C8) -> Localización: | G6: =CONCATENATE("Nº Lote: ",DATINF!C19) -> Nº Lote:
A7: =CONCATENATE("Observaciones: ",DATINF!C22) -> Observaciones:
A9: RESULTADOS OBTENIDOS: | E9: Fecha de ensayo: | H9: =DATINF!C1 -> 0
A11: =DATINF!A24 -> Nº ensayo | B11: LABORATORIO | D11: OBRA
B12: Proctor Modificado | D12: Equipo Radiactivo | H12: Compactación (%)
B13: Densidad Máxima (g/cm3) | C13: Humedad Óptima (%) | D13: Densidad "in situ" (g/cm3) | F13: Humedad "in situ" (%)
B15: =DATINF!C26 -> 0 | C15: =DATINF!D26 -> 0 | D15: =DATINF!E26 -> 0 | F15: =DATINF!F26 -> 0 | H15: =DATINF!G26
B16: =DATINF!C27 -> #N/A | C16: =DATINF!D27 -> #N/A | D16: =DATINF!E27 -> 0 | F16: =DATINF!F27 -> 0 | H16: =DATINF!G27
B17: =DATINF!C28 -> #N/A | C17: =DATINF!D28 -> #N/A | D17: =DATINF!E28 -> 0 | F17: =DATINF!F28 -> 0 | H17: =DATINF!G28
B18: =DATINF!C29 -> #N/A | C18: =DATINF!D29 -> #N/A | D18: =DATINF!E29 -> 0 | F18: =DATINF!F29 -> 0 | H18: =DATINF!G29
B19: =DATINF!C30 -> #N/A | C19: =DATINF!D30 -> #N/A | D19: =DATINF!E30 -> 0 | F19: =DATINF!F30 -> 0 | H19: =DATINF!G30
A20: =DATINF!A31 | B20: =DATINF!C31 -> #N/A | C20: =DATINF!D31 -> #N/A | D20: =DATINF!E31 -> 0 | F20: =DATINF!F31 -> 0 | H20: =DATINF!G31
A21: =DATINF!A32 | B21: =DATINF!C32 -> #N/A | C21: =DATINF!D32 -> #N/A | D21: =DATINF!E32 -> 0 | F21: =DATINF!F32 -> 0 | H21: =DATINF!G32
A22: =DATINF!A33 | B22: =DATINF!C33 -> #N/A | C22: =DATINF!D33 -> #N/A | D22: =DATINF!E33 -> 0 | F22: =DATINF!F33 -> 0 | H22: =DATINF!G33
A23: =DATINF!A34 | B23: =DATINF!C34 -> #N/A | C23: =DATINF!D34 -> #N/A | D23: =DATINF!E34 -> 0 | F23: =DATINF!F34 -> 0 | H23: =DATINF!G34
A24: =DATINF!A35 | B24: =DATINF!C35 -> #N/A | C24: =DATINF!D35 -> #N/A | D24: =DATINF!E35 -> 0 | F24: =DATINF!F35 -> 0 | H24: =DATINF!G35
A25: =DATINF!A36 | B25: =DATINF!C36 -> #N/A | C25: =DATINF!D36 -> #N/A | D25: =DATINF!E36 -> 0 | F25: =DATINF!F36 -> 0 | H25: =DATINF!G36
A26: =DATINF!A37 | B26: =DATINF!C37 -> #N/A | C26: =DATINF!D37 -> #N/A | D26: =DATINF!E37 -> 0 | F26: =DATINF!F37 -> 0 | H26: =DATINF!G37
A27: =DATINF!A38 | B27: =DATINF!C38 -> #N/A | C27: =DATINF!D38 -> #N/A | D27: =DATINF!E38 -> 0 | F27: =DATINF!F38 -> 0 | H27: =DATINF!G38
A28: =DATINF!A39 | B28: =DATINF!C39 -> #N/A | C28: =DATINF!D39 -> #N/A | D28: =DATINF!E39 -> 0 | F28: =DATINF!F39 -> 0 | H28: =DATINF!G39
A29: =DATINF!A40 | B29: =DATINF!C40 -> #N/A | C29: =DATINF!D40 -> #N/A | D29: =DATINF!E40 -> 0 | F29: =DATINF!F40 -> 0 | H29: =DATINF!G40
A30: MEDIA LOTE | D30: =DATINF!E42 -> #DIV/0! | F30: =DATINF!F42 -> #DIV/0! | H30: =DATINF!G42 -> #DIV/0!
A31: COEFICIENTE DE VARIACIÓN LOTE, V% | D31: =DATINF!E43 -> #DIV/0! | F31: =DATINF!F43 -> #DIV/0! | H31: --
A32: ESPECIFICACIÓN Art. 330.6.5.4 PG-3 | B32: CONDICIÓN 1: % Compactación media del lote obtenida | F32: ≥ | G32: =DATINF!S26 -> 1 | H32: =DATINF!K42 -> #DIV/0!
B33: CONDICIÓN 2: Ningún valor de densidad de los ensayos del lote di<despecificada - 0,03 g/cm3, Valor de densidad mínima (g/cm3) | F33: ≥ | G33: =(DATINF!C26*DATINF!S26)-0.03 -> -0.03 | H33: CUMPLE
B34: CONDICIÓN 3: 60% de los puntos entre las líneas de isosaturación y sobre la curva próctor | H34: --
A45: - Los resultados de este Informe sólo afectan al material sometido a ensayo
A46: - Este Informe no deberá reproducirse sin la aprobación de CYE CONTROL Y ESTUDIOS, S.L.
A47: Los resultados de este Informe sólo afectan al material sometido a ensayo
A50: Narón (A Coruña), | D50: =DATINF!C2 -> 0
A52: VºBº EL DIRECTOR DEL LABORATORIO EL JEFE DE ÁREA VS
A55: Fdo.: Gonzalo J. Guzmán Fdo.: María Díaz Calvo
A57: DESTINATARIOS DEL INFORME:
A58: =IF(DATINF!C9="","",DATINF!C9)
A59: =IF(DATINF!C11="","",DATINF!C11)
A60: =IF(DATINF!C13="","",DATINF!C13)
A61: =IF(DATINF!C15="","",DATINF!C15)
...
