Workbook

Sheet DATINF
A1: Fecha entrada (ensayo) | C1: 12-03-2026
A2: Fecha informe (firma) | C2: 12/03/2026
A3: Procedencia
B4: Cliente | C4: S. A. de Obras y Servicios, COPASA
A5: Obra | C5: RENOVACIÓN DE LAS VÍAS DEL RAMAL DE ACCESO AL PUERTO DE FERROL EN EL ÁMBITO DE TITULARIDAD DE LA APFSC HASTA SU CONEXIÓN CON EL NUEVO ACCESO FERROVIARO AL PUERTO EXTERIOR- DOTACIÓN DEL TERCER HILO" (P-1655)
A6: Ref Obra | C6: 0167/26
A7: Material | C7: Carga con Placa
A8: Orden trabajo | C8: 26/1503 | D8: =SUBSTITUTE(C8,"/","_") -> 26_1503
A9: Localización | C9: PK 0+060
A10: Destinatario1 | C10: S. A. de Obras y Servicios, COPASA Dirección: RUA DO PASEO, 25 - ENTLO. 32003 OURENSE OURENSE
A12: Destinatario2 | C12: -
A14: Destinatario3 | C14: -
A16: Destinatario4 | C16: -
A18: Destinatario5 | C18: -
A20: Climatología | C20: Soleado
A21: Temperatura ºC | C21: 15
A22: P.K. | C22: PK 0+060
A23: Capa | C23: Macadam (relleno saneo)
B24: Humedad del suelo
B25: Fplaca cm | C25: 60
A26: Tiempo total invertido (min) | C26: 50
B27: Observaciones
A29: Carga específica Mpa | B29: Lectura de flexímetros | E29: Asiento medio mm
A30: específica MPa | B30: 1 | C30: 2 | D30: 3
A31: Primer ciclo de carga
A32: 0 | B32: 0 | C32: 0 | D32: 0 | E32: =AVERAGE(B32:D32) -> 0
A33: 0.036 | B33: 0.15 | C33: 0.2 | D33: 0.3 | E33: =AVERAGE(B33:D33) -> 0.21666667
A34: 0.075 | B34: 0.48 | C34: 0.67 | D34: 1.1 | E34: =ROUND(AVERAGE(B34:D34),2) -> 0.75
A35: 0.107 | B35: 0.62 | C35: 0.93 | D35: 1.62 | E35: =AVERAGE(B35:D35) -> 1.0566667
A36: 0.143 | B36: 0.79 | C36: 1.2 | D36: 2.09 | E36: =ROUND(AVERAGE(B36:D36),2) -> 1.36 | F36: Ev1 (MPa): | G36: =ROUND(1.5*150*0.2/(E37-E34),0) -> 53
A37: 0.175 | B37: 0.94 | C37: 1.4 | D37: 2.48 | E37: =AVERAGE(B37:D37) -> 1.6066667
A38: 0.214 | B38: 1.15 | C38: 1.72 | D38: 2.96 | E38: =AVERAGE(B38:D38) -> 1.9433333
A39: 0.25 | B39: 1.36 | C39: 2.04 | D39: 3.32 | E39: =AVERAGE(B39:D39) -> 2.24
A40: =A39 -> 0.25 | B40: Descarga | E40: =E39 -> 2.24
A41: 0.125 | B41: 1.25 | C41: 1.91 | D41: 3.18 | E41: =AVERAGE(B41:D41) -> 2.1133333
A42: 0.0625 | B42: 1.08 | C42: 1.73 | D42: 3 | E42: =AVERAGE(B42:D42) -> 1.9366667
A43: 0 | B43: 0.79 | C43: 1.43 | D43: 2.65 | E43: =AVERAGE(B43:D43) -> 1.6233333
A44: =A43 -> 0 | B44: Segundo ciclo de carga | E44: =E43 -> 1.6233333
A45: 0.036 | B45: 0.9 | C45: 1.52 | D45: 2.77 | E45: =AVERAGE(B45:D45) -> 1.73
A46: 0.075 | B46: 1.01 | C46: 1.66 | D46: 2.91 | E46: =ROUND(AVERAGE(B46:D46),2) -> 1.86
...

Sheet INF
A2: INFORME DE ENSAYO DE CARGA CON PLACA NLT-357/98
A3: =CONCATENATE("Obra: ",DATINF!C5) -> Obra: RENOVACIÓN DE LAS VÍAS DEL RAMAL DE ACCESO AL PUERTO DE FERROL EN EL ÁMBITO DE TITULARIDAD DE LA APFSC HASTA SU CONEXIÓN CON EL NUEVO ACCESO FERROVIARO AL PUERTO EXTERIOR- DOTACIÓN DEL TERCER HILO" (P-1655)
A5: =CONCATENATE("Cliente: ",DATINF!C4) -> Cliente: S. A. de Obras y Servicios, COPASA | F5: =CONCATENATE("Ref. de obra: ",DATINF!C6) -> Ref. de obra: 0167/26
A6: =CONCATENATE("Procedencia: ",DATINF!C3) -> Procedencia: | F6: =CONCATENATE("Orden de trabajo: ",DATINF!C8) -> Orden de trabajo: 26/1503
A7: =CONCATENATE("Fecha ensayo: ",DATINF!C1) -> Fecha ensayo: 12-03-2026 | C7: =CONCATENATE("Climatología: ",DATINF!C20) -> Climatología: Soleado | F7: =CONCATENATE("Temperatura ºC: ",DATINF!C21) -> Temperatura ºC: 15
A8: =CONCATENATE("P.K.: ",DATINF!C22) -> P.K.: PK 0+060 | F8: =CONCATENATE("Capa: ",DATINF!C23) -> Capa: Macadam (relleno saneo)
A9: =CONCATENATE("Humedad suelo: ",DATINF!C24) -> Humedad suelo: | C9: F | D9: =CONCATENATE("placa: ",DATINF!C25, " cm") -> placa: 60 cm | F9: =CONCATENATE("Tiempo invertido (min): ",DATINF!C26) -> Tiempo invertido (min): 50
A11: =DATINF!A29 -> Carga específica Mpa | B11: Lectura de flexímetros | E11: Asiento medio mm
A12: específica MPa | B12: 1 | C12: 2 | D12: 3
A13: Primer ciclo de carga
A14: =DATINF!A32 -> 0 | B14: =DATINF!B32 -> 0 | C14: =DATINF!C32 -> 0 | D14: =DATINF!D32 -> 0 | E14: =DATINF!E32 -> 0 | F14: =IF(DATINF!F32="","",DATINF!F32) | G14: =IF(DATINF!G32="","",DATINF!G32)
A15: =DATINF!A33 -> 0.036 | B15: =DATINF!B33 -> 0.15 | C15: =DATINF!C33 -> 0.2 | D15: =DATINF!D33 -> 0.3 | E15: =DATINF!E33 -> 0.21666667 | F15: =IF(DATINF!F33="","",DATINF!F33) | G15: =IF(DATINF!G33="","",DATINF!G33)
A16: =DATINF!A34 -> 0.075 | B16: =DATINF!B34 -> 0.48 | C16: =DATINF!C34 -> 0.67 | D16: =DATINF!D34 -> 1.1 | E16: =DATINF!E34 -> 0.75 | F16: =IF(DATINF!F34="","",DATINF!F34) | G16: =IF(DATINF!G34="","",DATINF!G34)
A17: =DATINF!A35 -> 0.107 | B17: =DATINF!B35 -> 0.62 | C17: =DATINF!C35 -> 0.93 | D17: =DATINF!D35 -> 1.62 | E17: =DATINF!E35 -> 1.0566667 | F17: =IF(DATINF!F35="","",DATINF!F35) | G17: =IF(DATINF!G35="","",DATINF!G35)
A18: =DATINF!A36 -> 0.143 | B18: =DATINF!B36 -> 0.79 | C18: =DATINF!C36 -> 1.2 | D18: =DATINF!D36 -> 2.09 | E18: =DATINF!E36 -> 1.36 | F18: =IF(DATINF!F36="","",DATINF!F36) -> Ev1 (MPa): | G18: =IF(DATINF!G36="","",DATINF!G36) -> 53
A19: =DATINF!A37 -> 0.175 | B19: =DATINF!B37 -> 0.94 | C19: =DATINF!C37 -> 1.4 | D19: =DATINF!D37 -> 2.48 | E19: =DATINF!E37 -> 1.6066667 | F19: =IF(DATINF!F37="","",DATINF!F37) | G19: =IF(DATINF!G37="","",DATINF!G37)
A20: =DATINF!A38 -> 0.214 | B20: =DATINF!B38 -> 1.15 | C20: =DATINF!C38 -> 1.72 | D20: =DATINF!D38 -> 2.96 | E20: =DATINF!E38 -> 1.9433333
A21: =DATINF!A39 -> 0.25 | B21: =DATINF!B39 -> 1.36 | C21: =DATINF!C39 -> 2.04 | D21: =DATINF!D39 -> 3.32 | E21: =DATINF!E39 -> 2.24 | F21: =IF(DATINF!F39="","",DATINF!F39) | G21: =IF(DATINF!G39="","",DATINF!G39)
A22: =A21 -> 0.25 | B22: Descarga | F22: =IF(DATINF!F40="","",DATINF!F40) | G22: =IF(DATINF!G40="","",DATINF!G40)
A23: =DATINF!A41 -> 0.125 | B23: =DATINF!B41 -> 1.25 | C23: =DATINF!C41 -> 1.91 | D23: =DATINF!D41 -> 3.18 | E23: =DATINF!E41 -> 2.1133333 | F23: =IF(DATINF!F41="","",DATINF!F41) | G23: =IF(DATINF!G41="","",DATINF!G41)
A24: =DATINF!A42 -> 0.0625 | B24: =DATINF!B42 -> 1.08 | C24: =DATINF!C42 -> 1.73 | D24: =DATINF!D42 -> 3 | E24: =DATINF!E42 -> 1.9366667 | F24: =IF(DATINF!F42="","",DATINF!F42) | G24: =IF(DATINF!G42="","",DATINF!G42)
A25: =DATINF!A43 -> 0 | B25: =DATINF!B43 -> 0.79 | C25: =DATINF!C43 -> 1.43 | D25: =DATINF!D43 -> 2.65 | E25: =DATINF!E43 -> 1.6233333 | F25: =IF(DATINF!F43="","",DATINF!F43) | G25: =IF(DATINF!G43="","",DATINF!G43)
A26: =A25 -> 0 | B26: Segundo ciclo de carga | F26: =IF(DATINF!F44="","",DATINF!F44) | G26: =IF(DATINF!G44="","",DATINF!G44)
A27: =DATINF!A45 -> 0.036 | B27: =DATINF!B45 -> 0.9 | C27: =DATINF!C45 -> 1.52 | D27: =DATINF!D45 -> 2.77 | E27: =DATINF!E45 -> 1.73 | F27: =IF(DATINF!F45="","",DATINF!F45) | G27: =IF(DATINF!G45="","",DATINF!G45)
A28: =DATINF!A46 -> 0.075 | B28: =DATINF!B46 -> 1.01 | C28: =DATINF!C46 -> 1.66 | D28: =DATINF!D46 -> 2.91 | E28: =DATINF!E46 -> 1.86 | F28: =IF(DATINF!F46="","",DATINF!F46) | G28: =IF(DATINF!G46="","",DATINF!G46)
A29: =DATINF!A47 -> 0.107 | B29: =DATINF!B47 -> 1.16 | C29: =DATINF!C47 -> 1.74 | D29: =DATINF!D47 -> 3 | E29: =DATINF!E47 -> 1.97
A30: =DATINF!A48 -> 0.143 | B30: =DATINF!B48 -> 1.17 | C30: =DATINF!C48 -> 1.83 | D30: =DATINF!D48 -> 3.1 | E30: =DATINF!E48 -> 2.0333333 | F30: =IF(DATINF!F48="","",DATINF!F48) | G30: =IF(DATINF!G48="","",DATINF!G48)
A31: =DATINF!A49 -> 0.175 | B31: =DATINF!B49 -> 1.26 | C31: =DATINF!C49 -> 1.96 | D31: =DATINF!D49 -> 3.24 | E31: =DATINF!E49 -> 2.15 | F31: =IF(DATINF!F49="","",DATINF!F49) -> Ev2 (MPa): | G31: =IF(DATINF!G49="","",DATINF!G49) -> 155
A32: =DATINF!A50 -> 0.214 | B32: =DATINF!B50 -> 1.33 | C32: =DATINF!C50 -> 2.02 | D32: =DATINF!D50 -> 3.3 | E32: =DATINF!E50 -> 2.2166667 | F32: =IF(DATINF!F50="","",DATINF!F50) -> Ev2/Ev1: | G32: =IF(DATINF!G50="","",DATINF!G50) -> 2.92
A34: =CONCATENATE("Observaciones: ",DATINF!C27) -> Observaciones:
A56: - Los resultados de este Informe sólo afectan al material sometido a ensayo
A57: - Este Informe no deberá reproducirse sin la aprobación de CYE CONTROL Y ESTUDIOS, S.L.
C59: Narón (A Coruña), | E59: =DATINF!C2 -> 12/03/2026
A61: VºBº EL DIRECTOR DEL LABORATORIO | F61: JEFE DEL ÁREA VS
A63: Fdo.: Gonzalo J. Guzmán | F63: Fdo.: María Díaz Calvo
A64: =DATINF!C10 -> S. A. de Obras y Servicios, COPASA Dirección: RUA DO PASEO, 25 - ENTLO. 32003 OURENSE OURENSE | G64: Página -1/1-
